Workbook

Sheet NDDP NDVA
A1: revenue and expenditure | B1: Sr. No. | C1: District | D1: Crops | E1: Livestock | F1: Forestry and Logging | G1: Fishing and aquaculture | H1: Agriculture & Allied Activities | I1: Minign & Quarrying | J1: Primary Sector | K1: Manufacturing | L1: Electricity, Gas, Water Supply & Other Utility Services | M1: Construction | N1: Secondary Sector | O1: Industry | P1: Trade, Repair, Hotels & Restaurants | Q1: Railways | R1: Transport by means other than Railways | S1: Storage | T1: Comm. and services related to Broad. | U1: Financial Services | V1: R. Estate, O. Dwellings & Professional Services | W1: Public Admini- stration & Defence | X1: Other Services | Y1: Services/ Tertiary Sector | Z1: NDVA | AA1: Taxes on products | AB1: Less subsidies on products | AC1: NDDP | AD1: Popula- tion ('000) | AE1: Per capita District Domestic Product ( )
A2: 2011 | B2: 10 | C2: Ahmednagar | D2: 6042 | E2: 3513 | F2: 578 | G2: 14 | H2: 10147 | I2: 179 | J2: 10326 | K2: 5841 | L2: 509 | M2: 2170 | N2: 8521 | O2: 8700 | P2: 2770 | Q2: 145 | R2: 1011 | S2: 22 | T2: 364 | U2: 3276 | V2: 3985 | W2: 786 | X2: 1650 | Y2: 14009 | Z2: 32856 | AA2: 5376 | AB2: 867 | AC2: 37365 | AD2: 4565 | AE2: 81842
A3: 2012 | B3: 10 | C3: Ahmednagar | D3: 5023 | E3: 3632 | F3: 578 | G3: 8 | H3: 9242 | I3: 418 | J3: 9661 | K3: 6163 | L3: 518 | M3: 2037 | N3: 8718 | O3: 9136 | P3: 3002 | Q3: 148 | R3: 1094 | S3: 23 | T3: 374 | U3: 3475 | V3: 4219 | W3: 783 | X3: 1780 | Y3: 14897 | Z3: 33276 | AA3: 5668 | AB3: 1043 | AC3: 37901 | AD3: 4604 | AE3: 82327
A4: 2013 | B4: 10 | C4: Ahmednagar | D4: 6486 | E4: 4278 | F4: 555 | G4: 15 | H4: 11334 | I4: 93 | J4: 11427 | K4: 6955 | L4: 398 | M4: 2081 | N4: 9433 | O4: 9527 | P4: 2930 | Q4: 150 | R4: 1115 | S4: 23 | T4: 377 | U4: 3943 | V4: 4656 | W4: 797 | X4: 1963 | Y4: 15954 | Z4: 36815 | AA4: 6225 | AB4: 1083 | AC4: 41956 | AD4: 4642 | AE4: 90392
A5: 2014 | B5: 10 | C5: Ahmednagar | D5: 6130 | E5: 4675 | F5: 559 | G5: 15 | H5: 11380 | I5: 170 | J5: 11550 | K5: 7295 | L5: 527 | M5: 2249 | N5: 10072 | O5: 10242 | P5: 2997 | Q5: 168 | R5: 1241 | S5: 24 | T5: 432 | U5: 4231 | V5: 5201 | W5: 818 | X5: 2205 | Y5: 17317 | Z5: 38938 | AA5: 6598 | AB5: 1055 | AC5: 44481 | AD5: 4679 | AE5: 95060
A6: 2015 | B6: 10 | C6: Ahmednagar | D6: 4736 | E6: 4855 | F6: 562 | G6: 9 | H6: 10161 | I6: 241 | J6: 10402 | K6: 8223 | L6: 562 | M6: 2301 | N6: 11086 | O6: 11326 | P6: 2998 | Q6: 179 | R6: 1416 | S6: 24 | T6: 528 | U6: 4494 | V6: 5747 | W6: 871 | X6: 2441 | Y6: 18699 | Z6: 40186 | AA6: 6778 | AB6: 844 | AC6: 46121 | AD6: 4717 | AE6: 97782
A7: 2016 | B7: 10 | C7: Ahmednagar | D7: 5453 | E7: 5173 | F7: 596 | G7: 9 | H7: 11232 | I7: 91 | J7: 11324 | K7: 8960 | L7: 599 | M7: 2419 | N7: 11977 | O7: 12069 | P7: 3377 | Q7: 205 | R7: 1548 | S7: 24 | T7: 491 | U7: 4750 | V7: 6325 | W7: 944 | X7: 2723 | Y7: 20387 | Z7: 43688 | AA7: 7309 | AB7: 743 | AC7: 50254 | AD7: 4751 | AE7: 105777
A8: 2017 | B8: 10 | C8: Ahmednagar | D8: 7080 | E8: 5468 | F8: 593 | G8: 12 | H8: 13153 | I8: 23 | J8: 13176 | K8: 9722 | L8: 632 | M8: 2450 | N8: 12804 | O8: 12827 | P8: 3612 | Q8: 236 | R8: 1657 | S8: 26 | T8: 421 | U8: 4880 | V8: 6703 | W8: 1028 | X8: 2925 | Y8: 21487 | Z8: 47467 | AA8: 8127 | AB8: 720 | AC8: 54874 | AD8: 4783 | AE8: 114733
A9: 2018 | B9: 10 | C9: Ahmednagar | D9: 6264 | E9: 6033 | F9: 619 | G9: 13 | H9: 12929 | I9: 25 | J9: 12954 | K9: 10255 | L9: 697 | M9: 2466 | N9: 13418 | O9: 13443 | P9: 3903 | Q9: 227 | R9: 1769 | S9: 26 | T9: 413 | U9: 5096 | V9: 7344 | W9: 1059 | X9: 3163 | Y9: 22999 | Z9: 49372 | AA9: 8795 | AB9: 754 | AC9: 57413 | AD9: 4814 | AE9: 119254
A10: 2019 | B10: 10 | C10: Ahmednagar | D10: 5671 | E10: 6303 | F10: 615 | G10: 19 | H10: 12609 | I10: 301 | J10: 12910 | K10: 9982 | L10: 725 | M10: 2466 | N10: 13173 | O10: 13474 | P10: 4078 | Q10: 233 | R10: 1871 | S10: 27 | T10: 459 | U10: 5221 | V10: 7868 | W10: 1233 | X10: 3452 | Y10: 24442 | Z10: 50525 | AA10: 8936 | AB10: 816 | AC10: 58645 | AD10: 4846 | AE10: 121024
A11: 2011 | B11: 25 | C11: Akola | D11: 1734 | E11: 234 | F11: 144 | G11: 13 | H11: 2125 | I11: 75 | J11: 2200 | K11: 2365 | L11: 206 | M11: 879 | N11: 3450 | O11: 3525 | P11: 1122 | Q11: 59 | R11: 409 | S11: 9 | T11: 147 | U11: 1326 | V11: 1614 | W11: 318 | X11: 668 | Y11: 5673 | Z11: 11323 | AA11: 1853 | AB11: 299 | AC11: 12877 | AD11: 1825 | AE11: 70551
A12: 2012 | B12: 25 | C12: Akola | D12: 2131 | E12: 245 | F12: 140 | G12: 13 | H12: 2530 | I12: 86 | J12: 2616 | K12: 2521 | L12: 212 | M12: 833 | N12: 3566 | O12: 3652 | P12: 1228 | Q12: 61 | R12: 447 | S12: 9 | T12: 153 | U12: 1422 | V12: 1726 | W12: 320 | X12: 728 | Y12: 6094 | Z12: 12276 | AA12: 2090 | AB12: 385 | AC12: 13982 | AD12: 1845 | AE12: 75801
A13: 2013 | B13: 25 | C13: Akola | D13: 2179 | E13: 281 | F13: 132 | G13: 21 | H13: 2613 | I13: 145 | J13: 2758 | K13: 2788 | L13: 159 | M13: 834 | N13: 3781 | O13: 3926 | P13: 1174 | Q13: 60 | R13: 447 | S13: 9 | T13: 151 | U13: 1580 | V13: 1866 | W13: 319 | X13: 787 | Y13: 6394 | Z13: 12933 | AA13: 2187 | AB13: 381 | AC13: 14740 | AD13: 1864 | AE13: 79081
... A307: 2019 | B307: 28 | C307: Yavatmal | D307: 2704 | E307: 502 | F307: 920 | G307: 44 | H307: 4169 | I307: 818 | J307: 4987 | K307: 4238 | L307: 308 | M307: 1047 | N307: 5592 | O307: 6411 | P307: 1731 | Q307: 99 | R307: 794 | S307: 12 | T307: 195 | U307: 2217 | V307: 3340 | W307: 524 | X307: 1466 | Y307: 10377 | Z307: 20957 | AA307: 3703 | AB307: 338 | AC307: 24322 | AD307: 2961 | AE307: 82132

Sheet GDDP GDVA
A1: Financial Year | B1: Sr. No. | C1: District | D1: Crops | E1: Livestock | F1: Forestry and Logging | G1: Fishing and aquaculture | H1: Agriculture & Allied Activities | I1: Minign & Quarrying | J1: Primary Sector | K1: Manufacturing | L1: Electricity, Gas, Water Supply & Other Utility Services | M1: Construction | N1: Secondary Sector | O1: Industry | P1: Trade, Repair, Hotels & Restaurants | Q1: Railways | R1: Transport by means other than Railways | S1: Storage | T1: Comm. and services related to Broad. | U1: Financial Services | V1: R. Estate, O. Dwellings & Professional Services | W1: Public Admini- stration & Defence | X1: Other Services | Y1: Services/ Tertiary Sector | Z1: GDVA | AA1: Taxes on products | AB1: Less subsidies on products | AC1: GDDP | AD1: Popula- tion ('000) | AE1: Per capita District Domestic Product ( )
A2: 2011 | B2: 10 | C2: Ahmednagar | D2: 6405 | E2: 3563 | F2: 584 | G2: 16 | H2: 10568 | I2: 204 | J2: 10772 | K2: 6938 | L2: 756 | M2: 2271 | N2: 9965 | O2: 10169 | P2: 2978 | Q2: 169 | R2: 1176 | S2: 26 | T2: 448 | U2: 3323 | V2: 5382 | W2: 1102 | X2: 1879 | Y2: 16482 | Z2: 37219 | AA2: 5271 | AB2: 850 | AC2: 41640 | AD2: 4565 | AE2: 91207
A3: 2012 | B3: 10 | C3: Ahmednagar | D3: 5349 | E3: 3686 | F3: 584 | G3: 9 | H3: 9629 | I3: 473 | J3: 10102 | K3: 7380 | L3: 781 | M3: 2149 | N3: 10310 | O3: 10783 | P3: 3239 | Q3: 172 | R3: 1272 | S3: 26 | T3: 462 | U3: 3532 | V3: 5738 | W3: 1104 | X3: 2013 | Y3: 17557 | Z3: 37969 | AA3: 5569 | AB3: 1025 | AC3: 42513 | AD3: 4604 | AE3: 92346
A4: 2013 | B4: 10 | C4: Ahmednagar | D4: 6868 | E4: 4343 | F4: 561 | G4: 17 | H4: 11788 | I4: 109 | J4: 11897 | K4: 8125 | L4: 748 | M4: 2233 | N4: 11106 | O4: 11214 | P4: 3195 | Q4: 178 | R4: 1320 | S4: 28 | T4: 522 | U4: 4007 | V4: 6400 | W4: 1132 | X4: 2215 | Y4: 18997 | Z4: 42000 | AA4: 6092 | AB4: 1060 | AC4: 47032 | AD4: 4642 | AE4: 101328
A5: 2014 | B5: 10 | C5: Ahmednagar | D5: 6593 | E5: 4746 | F5: 564 | G5: 18 | H5: 11921 | I5: 198 | J5: 12120 | K5: 8515 | L5: 855 | M5: 2403 | N5: 11773 | O5: 11972 | P5: 3290 | Q5: 201 | R5: 1453 | S5: 29 | T5: 574 | U5: 4307 | V5: 7193 | W5: 1157 | X5: 2469 | Y5: 20672 | Z5: 44565 | AA5: 6461 | AB5: 1033 | AC5: 49993 | AD5: 4679 | AE5: 106840
A6: 2015 | B6: 10 | C6: Ahmednagar | D6: 5139 | E6: 4927 | F6: 566 | G6: 10 | H6: 10641 | I6: 253 | J6: 10894 | K6: 9430 | L6: 895 | M6: 2447 | N6: 12773 | O6: 13025 | P6: 3303 | Q6: 215 | R6: 1621 | S6: 29 | T6: 680 | U6: 4567 | V6: 7856 | W6: 1215 | X6: 2704 | Y6: 22192 | Z6: 45858 | AA6: 6666 | AB6: 830 | AC6: 51695 | AD6: 4717 | AE6: 109599
A7: 2016 | B7: 10 | C7: Ahmednagar | D7: 5834 | E7: 5245 | F7: 602 | G7: 11 | H7: 11693 | I7: 95 | J7: 11787 | K7: 10096 | L7: 925 | M7: 2586 | N7: 13607 | O7: 13702 | P7: 3718 | Q7: 246 | R7: 1765 | S7: 29 | T7: 660 | U7: 4830 | V7: 8612 | W7: 1308 | X7: 3014 | Y7: 24182 | Z7: 49577 | AA7: 7193 | AB7: 731 | AC7: 56039 | AD7: 4751 | AE7: 117954
A8: 2017 | B8: 10 | C8: Ahmednagar | D8: 7629 | E8: 5540 | F8: 599 | G8: 14 | H8: 13781 | I8: 24 | J8: 13805 | K8: 10924 | L8: 1024 | M8: 2637 | N8: 14585 | O8: 14608 | P8: 4021 | Q8: 281 | R8: 1917 | S8: 31 | T8: 623 | U8: 4961 | V8: 9083 | W8: 1393 | X8: 3264 | Y8: 25574 | Z8: 53964 | AA8: 7984 | AB8: 707 | AC8: 61240 | AD8: 4783 | AE8: 128044
A9: 2018 | B9: 10 | C9: Ahmednagar | D9: 6799 | E9: 6105 | F9: 625 | G9: 15 | H9: 13545 | I9: 26 | J9: 13571 | K9: 11520 | L9: 1103 | M9: 2677 | N9: 15300 | O9: 15326 | P9: 4352 | Q9: 277 | R9: 2066 | S9: 32 | T9: 646 | U9: 5192 | V9: 9869 | W9: 1440 | X9: 3530 | Y9: 27404 | Z9: 56275 | AA9: 8645 | AB9: 741 | AC9: 64179 | AD9: 4814 | AE9: 133307
A10: 2019 | B10: 10 | C10: Ahmednagar | D10: 6156 | E10: 6379 | F10: 621 | G10: 22 | H10: 13178 | I10: 309 | J10: 13487 | K10: 11234 | L10: 1149 | M10: 2681 | N10: 15064 | O10: 15373 | P10: 4556 | Q10: 285 | R10: 2188 | S10: 33 | T10: 720 | U10: 5328 | V10: 10593 | W10: 1680 | X10: 3859 | Y10: 29243 | Z10: 57794 | AA10: 8789 | AB10: 802 | AC10: 65780 | AD10: 4846 | AE10: 135749
A11: 2011 | B11: 25 | C11: Akola | D11: 1838 | E11: 238 | F11: 145 | G11: 15 | H11: 2236 | I11: 85 | J11: 2321 | K11: 2809 | L11: 306 | M11: 920 | N11: 4035 | O11: 4120 | P11: 1206 | Q11: 68 | R11: 476 | S11: 11 | T11: 181 | U11: 1345 | V11: 2179 | W11: 446 | X11: 761 | Y11: 6674 | Z11: 13030 | AA11: 1846 | AB11: 298 | AC11: 14578 | AD11: 1825 | AE11: 79873
A12: 2012 | B12: 25 | C12: Akola | D12: 2269 | E12: 249 | F12: 142 | G12: 15 | H12: 2675 | I12: 97 | J12: 2772 | K12: 3018 | L12: 319 | M12: 879 | N12: 4216 | O12: 4313 | P12: 1324 | Q12: 70 | R12: 520 | S12: 11 | T12: 189 | U12: 1445 | V12: 2346 | W12: 451 | X12: 823 | Y12: 7180 | Z12: 14168 | AA12: 2077 | AB12: 382 | AC12: 15863 | AD12: 1845 | AE12: 86000
A13: 2013 | B13: 25 | C13: Akola | D13: 2307 | E13: 285 | F13: 134 | G13: 24 | H13: 2750 | I13: 168 | J13: 2918 | K13: 3257 | L13: 300 | M13: 895 | N13: 4452 | O13: 4620 | P13: 1281 | Q13: 71 | R13: 529 | S13: 11 | T13: 209 | U13: 1606 | V13: 2566 | W13: 454 | X13: 888 | Y13: 7615 | Z13: 14985 | AA13: 2174 | AB13: 378 | AC13: 16781 | AD13: 1864 | AE13: 90033
... A307: 2019 | B307: 28 | C307: Yavatmal | D307: 2935 | E307: 508 | F307: 929 | G307: 50 | H307: 4421 | I307: 841 | J307: 5262 | K307: 4791 | L307: 490 | M307: 1144 | N307: 6424 | O307: 7265 | P307: 1943 | Q307: 122 | R307: 933 | S307: 14 | T307: 307 | U307: 2272 | V307: 4518 | W307: 716 | X307: 1646 | Y307: 12471 | Z307: 24158 | AA307: 3672 | AB307: 335 | AC307: 27494 | AD307: 2961 | AE307: 92846

Sheet Gram Panchayat Income & Expendi
A1: Year | B1: District | C1: Land and other property taxes | D1: Other taxes and charges | E1: Total Tax | F1: Government Grants | G1: Contribution, donations and other grants | H1: Total grants and contributions | I1: Other deposits | J1: Total Income | K1: Administration | L1: Health and Hygiene | M1: Public Works | N1: Public Lighting | O1: Education | P1: Public Welfare | Q1: Other Expenses | R1: Total Expenditure
A2: 2009 | B2: Ahmadnagar | C2: 868 | D2: 1287 | E2: 2155 | F2: 2505 | G2: 1867 | H2: 4372 | I2: 1090 | J2: 7617 | K2: 2687 | L2: 1612 | M2: 1792 | N2: 203 | O2: 38 | P2: 19 | Q2: 15 | R2: 6366
A3: 2010 | B3: Ahmadnagar | C3: 1738 | D3: 837 | E3: 2575 | F3: 2302 | G3: 2172 | H3: 4474 | I3: 68 | J3: 7117 | K3: 2212 | L3: 1820 | M3: 1960 | N3: 296 | O3: 235 | P3: 66 | Q3: 16 | R3: 6605
A4: 2011 | B4: Ahmadnagar | C4: 1125 | D4: 1576 | E4: 2701 | F4: 4561 | G4: 2759 | H4: 7320 | I4: 61 | J4: 10082 | K4: 2767 | L4: 2111 | M4: 2996 | N4: 336 | O4: 246 | P4: 28 | Q4: 58 | R4: 8543
A5: 2012 | B5: Ahmadnagar | C5: 2005 | D5: 1970 | E5: 3975 | F5: 5437 | G5: 3141 | H5: 8578 | I5: 945 | J5: 13498 | K5: 4198 | L5: 3646 | M5: 2738 | N5: 484 | O5: 679 | P5: 443 | Q5: 583 | R5: 12770
A6: 2013 | B6: Ahmadnagar | C6: 2315 | D6: 2537 | E6: 4852 | F6: 4494 | G6: 3031 | H6: 7525 | I6: 1 | J6: 12378 | K6: 3864 | L6: 2911 | M6: 4006 | N6: 451 | O6: 390 | P6: 40 | Q6: 96 | R6: 11758
A7: 2014 | B7: Ahmadnagar | C7: 2680 | D7: 2526 | E7: 5206 | F7: 4911 | G7: 4141 | H7: 9052 | I7: 2 | J7: 14260 | K7: 4577 | L7: 3225 | M7: 3766 | N7: 455 | O7: 564 | P7: 149 | Q7: 428 | R7: 13164
A8: 2015 | B8: Ahmadnagar | C8: 1801 | D8: 2382 | E8: 4183 | F8: 3340 | G8: 3460 | H8: 6800 | I8: 2 | J8: 10985 | K8: 4759 | L8: 3038 | M8: 3475 | N8: 500 | O8: 492 | P8: 181 | Q8: 20 | R8: 12465
A9: 2016 | B9: Ahmadnagar | C9: 2857 | D9: 2676 | E9: 5533 | F9: 2867 | G9: 3685 | H9: 6552 | I9: 85 | J9: 12170 | K9: 4177 | L9: 3169 | M9: 3169 | N9: 458 | O9: 422 | P9: 200 | Q9: 16 | R9: 11612
A10: 2017 | B10: Ahmadnagar | C10: 3206 | D10: 2730 | E10: 5936 | F10: 2921 | G10: 3218 | H10: 6139 | I10: 102 | J10: 12176 | K10: 4548 | L10: 3187 | M10: 3142 | N10: 477 | O10: 463 | P10: 208 | Q10: 23 | R10: 12047
A11: 2018 | B11: Ahmadnagar | C11: 3178 | D11: 1041 | E11: 4219 | F11: 4227 | G11: 3286 | H11: 7513 | I11: 112 | J11: 11844 | K11: 3575 | L11: 1977 | M11: 3307 | N11: 544 | O11: 475 | P11: 357 | Q11: 264 | R11: 10498
A12: 2019 | B12: Ahmadnagar | C12: 2777 | D12: 2489 | E12: 5267 | F12: 5256 | G12: 2425 | H12: 7681 | I12: 96 | J12: 13044 | K12: 3704 | L12: 3792 | M12: 5158 | N12: 524 | O12: 442 | P12: 348 | Q12: 65 | R12: 14032
A13: 2020 | B13: Ahmadnagar | C13: 2921 | D13: 2614 | E13: 5535 | F13: 5522 | G13: 2552 | H13: 8074 | I13: 102 | J13: 13711 | K13: 3891 | L13: 3985 | M13: 5418 | N13: 555 | O13: 466 | P13: 368 | Q13: 71 | R13: 14754
... A259: 2017 | B259: Washim | C259: 1245 | D259: 186 | E259: 1431 | F259: 10113 | G259: 196 | H259: 10309 | I259: 516 | J259: 12256 | K259: 601 | L259: 290 | M259: 8711 | N259: 146 | O259: 6 | P259: 114 | Q259: 1425 | R259: 11292
A260: 2018 | B260: Washim
A261: 2019 | B261: Washim | C261: 1157 | D261: 249 | E261: 1406 | F261: 10403 | G261: 60 | H261: 10463 | I261: 839 | J261: 12708 | K261: 507 | L261: 354 | M261: 4657 | N261: 1044 | O261: 12 | P261: 141 | Q261: 2496 | R261: 9212
A262: 2020 | B262: Washim | C262: 798 | D262: 437 | E262: 1235 | F262: 6132 | G262: 1285 | H262: 7418 | I262: 1603 | J262: 10255 | K262: 728 | L262: 331 | M262: 4155 | N262: 87 | O262: 17 | P262: 77 | Q262: 752 | R262: 6148
A263: 2021 | B263: Washim | C263: 1360 | D263: 524 | E263: 1883 | F263: 7119 | G263: 72 | H263: 7191 | I263: 659 | J263: 9733 | K263: 291 | L263: 443 | M263: 3573 | N263: 1803 | O263: 25 | P263: 123 | Q263: 3210 | R263: 9469
A264: 2012 | B264: Yavatmal | C264: 1055 | D264: 112 | E264: 1167 | F264: 2086 | G264: 497 | H264: 2583 | I264: 930 | J264: 4680 | K264: 475 | L264: 495 | M264: 340 | N264: 456 | O264: 521 | P264: 282 | Q264: 707 | R264: 3276
A265: 2013 | B265: Yavatmal | C265: 2921 | D265: 415 | E265: 3336 | F265: 4694 | G265: 1299 | H265: 5993 | I265: 1921 | J265: 11250 | K265: 1166 | L265: 1717 | M265: 4171 | N265: 842 | O265: 357 | P265: 277 | Q265: 2993 | R265: 11522
A266: 2014 | B266: Yavatmal | C266: 2191 | D266: 515 | E266: 2706 | F266: 2426 | G266: 1378 | H266: 3804 | I266: 276 | J266: 6786 | K266: 669 | L266: 1142 | M266: 2250 | N266: 944 | O266: 150 | P266: 389 | Q266: 940 | R266: 6483
A267: 2015 | B267: Yavatmal | C267: 1247 | D267: 641 | E267: 1887 | F267: 4793 | G267: 1235 | H267: 6028 | I267: 1779 | J267: 9694 | K267: 1306 | L267: 1633 | M267: 3241 | N267: 399 | O267: 344 | P267: 240 | Q267: 924 | R267: 8087
A268: 2016 | B268: Yavatmal | C268: 4587 | D268: 325 | E268: 4911 | F268: 8179 | G268: 2330 | H268: 10510 | I268: 376 | J268: 15797 | K268: 1913 | L268: 1986 | M268: 5592 | N268: 736 | O268: 316 | P268: 564 | Q268: 2516 | R268: 13622
A269: 2017 | B269: Yavatmal | C269: 1092 | D269: 1898 | E269: 2990 | F269: 11001 | G269: 2543 | H269: 13543 | I269: 2064 | J269: 18598 | K269: 1576 | L269: 3094 | M269: 2250 | N269: 522 | O269: 857 | P269: 182 | Q269: 8654 | R269: 17135
A270: 2018 | B270: Yavatmal | C270: 1873 | D270: 1129 | E270: 3002 | F270: 13353 | G270: 1221 | H270: 14574 | I270: 508 | J270: 18085 | K270: 1209 | L270: 2545 | M270: 4855 | N270: 1069 | O270: 1735 | P270: 2252 | Q270: 2884 | R270: 16549
A271: 2019 | B271: Yavatmal | C271: 2000 | D271: 1148 | E271: 3148 | F271: 18465 | G271: 506 | H271: 18971 | I271: 1442 | J271: 23562 | K271: 1094 | L271: 2655 | M271: 8239 | N271: 372 | O271: 2409 | P271: 277 | Q271: 14501 | R271: 29546
A272: 2020 | B272: Yavatmal | C272: 2333 | D272: 1488 | E272: 3821 | F272: 12563 | G272: 764 | H272: 13327 | I272: 915 | J272: 18063 | K272: 1321 | L272: 2550 | M272: 5104 | N272: 740 | O272: 1142 | P272: 526 | Q272: 5198 | R272: 16580
... A349: 2021 | B349: Kolhapur | C349: 7345 | D349: 3540 | E349: 10885 | F349: 4040 | G349: 2458 | H349: 6498 | I349: 3825 | J349: 21208 | K349: 6475 | L349: 3455 | M349: 3335 | N349: 646 | O349: 64 | P349: 991 | Q349: 4433 | R349: 19398

Sheet Clean Jilla Parishad Income and
A1: District | B1: Year | C1: Opening Balance | D1: Revenue from self-made tools | E1: Government subsidies | F1: Purposive grants | G1: Establishment grants | H1: Grants for Plan Scheme | I1: Other Statutory grants | J1: For Agency Schemes | K1: Total Grants | L1: Other sources of income | M1: Capital receipts | N1: Total receipts | O1: Total Income (C+M) | P1: General Administration | Q1: Education | R1: Public Works | S1: Irrigation | T1: Agriculture | U1: Animal Husbandary | V1: Forests | W1: Public Health | X1: Social Welfare | Y1: Other Expenses | Z1: Total Revenue Expenditure | AA1: Capital Expenditure | AB1: Total Expenses
A2: Ahmadnagar | B2: =IF('Jilla Parishad Income & Expendi'!B2="", "", VALUE(SUBSTITUTE('Jilla Parishad Income & Expendi'!B2, ",", ""))) -> 2012 | C2: =IF('Jilla Parishad Income & Expendi'!C2="", "", VALUE(SUBSTITUTE('Jilla Parishad Income & Expendi'!C2, ",", ""))) -> 22558 | D2: =IF('Jilla Parishad Income & Expendi'!D2="", "", VALUE(SUBSTITUTE('Jilla Parishad Income & Expendi'!D2, ",", ""))) -> 215 | E2: =IF('Jilla Parishad Income & Expendi'!E2="", "", VALUE(SUBSTITUTE('Jilla Parishad Income & Expendi'!E2, ",", ""))) | F2: =IF('Jilla Parishad Income & Expendi'!F2="", "", VALUE(SUBSTITUTE('Jilla Parishad Income & Expendi'!F2, ",", ""))) -> 79949 | G2: =IF('Jilla Parishad Income & Expendi'!G2="", "", VALUE(SUBSTITUTE('Jilla Parishad Income & Expendi'!G2, ",", ""))) -> 11644 | H2: =IF('Jilla Parishad Income & Expendi'!H2="", "", VALUE(SUBSTITUTE('Jilla Parishad Income & Expendi'!H2, ",", ""))) -> 25133 | I2: =IF('Jilla Parishad Income & Expendi'!I2="", "", VALUE(SUBSTITUTE('Jilla Parishad Income & Expendi'!I2, ",", ""))) -> 0 | J2: =IF('Jilla Parishad Income & Expendi'!J2="", "", VALUE(SUBSTITUTE('Jilla Parishad Income & Expendi'!J2, ",", ""))) -> 82 | K2: =SUM(F2:J2) -> 116808 | L2: =IF('Jilla Parishad Income & Expendi'!K2="", "", VALUE(SUBSTITUTE('Jilla Parishad Income & Expendi'!K2, ",", ""))) -> 1045 | M2: =IF('Jilla Parishad Income & Expendi'!L2="", "", VALUE(SUBSTITUTE('Jilla Parishad Income & Expendi'!L2, ",", ""))) -> 3221 | N2: =IF('Jilla Parishad Income & Expendi'!M2="", "", VALUE(SUBSTITUTE('Jilla Parishad Income & Expendi'!M2, ",", ""))) -> 121289 | O2: =IF('Jilla Parishad Income & Expendi'!N2="", "", VALUE(SUBSTITUTE('Jilla Parishad Income & Expendi'!N2, ",", ""))) -> 143847 | P2: =IF('Jilla Parishad Income & Expendi'!O2="", "", VALUE(SUBSTITUTE('Jilla Parishad Income & Expendi'!O2, ",", ""))) -> 6686 | Q2: =IF('Jilla Parishad Income & Expendi'!P2="", "", VALUE(SUBSTITUTE('Jilla Parishad Income & Expendi'!P2, ",", ""))) -> 49386 | R2: =IF('Jilla Parishad Income & Expendi'!Q2="", "", VALUE(SUBSTITUTE('Jilla Parishad Income & Expendi'!Q2, ",", ""))) -> 6692 | S2: =IF('Jilla Parishad Income & Expendi'!R2="", "", VALUE(SUBSTITUTE('Jilla Parishad Income & Expendi'!R2, ",", ""))) -> 1945 | ... AD2: =IF('Jilla Parishad Income & Expendi'!AC2="", "", VALUE(SUBSTITUTE('Jilla Parishad Income & Expendi'!AC2, ",", "")))
A3: Ahmadnagar | B3: =IF('Jilla Parishad Income & Expendi'!B3="", "", VALUE(SUBSTITUTE('Jilla Parishad Income & Expendi'!B3, ",", ""))) -> 2013 | C3: =IF('Jilla Parishad Income & Expendi'!C3="", "", VALUE(SUBSTITUTE('Jilla Parishad Income & Expendi'!C3, ",", ""))) -> 27560 | D3: =IF('Jilla Parishad Income & Expendi'!D3="", "", VALUE(SUBSTITUTE('Jilla Parishad Income & Expendi'!D3, ",", ""))) -> 5069 | E3: =IF('Jilla Parishad Income & Expendi'!E3="", "", VALUE(SUBSTITUTE('Jilla Parishad Income & Expendi'!E3, ",", ""))) | F3: =IF('Jilla Parishad Income & Expendi'!F3="", "", VALUE(SUBSTITUTE('Jilla Parishad Income & Expendi'!F3, ",", ""))) -> 75857 | G3: =IF('Jilla Parishad Income & Expendi'!G3="", "", VALUE(SUBSTITUTE('Jilla Parishad Income & Expendi'!G3, ",", ""))) -> 13757 | H3: =IF('Jilla Parishad Income & Expendi'!H3="", "", VALUE(SUBSTITUTE('Jilla Parishad Income & Expendi'!H3, ",", ""))) -> 22792 | I3: =IF('Jilla Parishad Income & Expendi'!I3="", "", VALUE(SUBSTITUTE('Jilla Parishad Income & Expendi'!I3, ",", ""))) -> 104672 | J3: =IF('Jilla Parishad Income & Expendi'!J3="", "", VALUE(SUBSTITUTE('Jilla Parishad Income & Expendi'!J3, ",", ""))) -> 8225 | K3: =SUM(F3:J3) -> 225303 | L3: =IF('Jilla Parishad Income & Expendi'!K3="", "", VALUE(SUBSTITUTE('Jilla Parishad Income & Expendi'!K3, ",", ""))) -> 0 | M3: =IF('Jilla Parishad Income & Expendi'!L3="", "", VALUE(SUBSTITUTE('Jilla Parishad Income & Expendi'!L3, ",", ""))) -> 12217 | N3: =IF('Jilla Parishad Income & Expendi'!M3="", "", VALUE(SUBSTITUTE('Jilla Parishad Income & Expendi'!M3, ",", ""))) -> 242589 | O3: =IF('Jilla Parishad Income & Expendi'!N3="", "", VALUE(SUBSTITUTE('Jilla Parishad Income & Expendi'!N3, ",", ""))) -> 270149 | P3: =IF('Jilla Parishad Income & Expendi'!O3="", "", VALUE(SUBSTITUTE('Jilla Parishad Income & Expendi'!O3, ",", ""))) -> 755.02 | Q3: =IF('Jilla Parishad Income & Expendi'!P3="", "", VALUE(SUBSTITUTE('Jilla Parishad Income & Expendi'!P3, ",", ""))) -> 54878.85 | R3: =IF('Jilla Parishad Income & Expendi'!Q3="", "", VALUE(SUBSTITUTE('Jilla Parishad Income & Expendi'!Q3, ",", ""))) -> 6710.03 | S3: =IF('Jilla Parishad Income & Expendi'!R3="", "", VALUE(SUBSTITUTE('Jilla Parishad Income & Expendi'!R3, ",", ""))) -> 2131.6 | ... AD3: =IF('Jilla Parishad Income & Expendi'!AC3="", "", VALUE(SUBSTITUTE('Jilla Parishad Income & Expendi'!AC3, ",", "")))
A4: Ahmadnagar | B4: =IF('Jilla Parishad Income & Expendi'!B4="", "", VALUE(SUBSTITUTE('Jilla Parishad Income & Expendi'!B4, ",", ""))) -> 2014 | C4: =IF('Jilla Parishad Income & Expendi'!C4="", "", VALUE(SUBSTITUTE('Jilla Parishad Income & Expendi'!C4, ",", ""))) -> 30282 | D4: =IF('Jilla Parishad Income & Expendi'!D4="", "", VALUE(SUBSTITUTE('Jilla Parishad Income & Expendi'!D4, ",", ""))) -> 12775 | E4: =IF('Jilla Parishad Income & Expendi'!E4="", "", VALUE(SUBSTITUTE('Jilla Parishad Income & Expendi'!E4, ",", ""))) | F4: =IF('Jilla Parishad Income & Expendi'!F4="", "", VALUE(SUBSTITUTE('Jilla Parishad Income & Expendi'!F4, ",", ""))) -> 88311 | G4: =IF('Jilla Parishad Income & Expendi'!G4="", "", VALUE(SUBSTITUTE('Jilla Parishad Income & Expendi'!G4, ",", ""))) -> 13970 | H4: =IF('Jilla Parishad Income & Expendi'!H4="", "", VALUE(SUBSTITUTE('Jilla Parishad Income & Expendi'!H4, ",", ""))) -> 27567 | I4: =IF('Jilla Parishad Income & Expendi'!I4="", "", VALUE(SUBSTITUTE('Jilla Parishad Income & Expendi'!I4, ",", ""))) -> 98665 | J4: =IF('Jilla Parishad Income & Expendi'!J4="", "", VALUE(SUBSTITUTE('Jilla Parishad Income & Expendi'!J4, ",", ""))) -> 8806 | K4: =SUM(F4:J4) -> 237319 | L4: =IF('Jilla Parishad Income & Expendi'!K4="", "", VALUE(SUBSTITUTE('Jilla Parishad Income & Expendi'!K4, ",", ""))) -> 0 | M4: =IF('Jilla Parishad Income & Expendi'!L4="", "", VALUE(SUBSTITUTE('Jilla Parishad Income & Expendi'!L4, ",", ""))) -> 59226 | N4: =IF('Jilla Parishad Income & Expendi'!M4="", "", VALUE(SUBSTITUTE('Jilla Parishad Income & Expendi'!M4, ",", ""))) -> 309320 | O4: =IF('Jilla Parishad Income & Expendi'!N4="", "", VALUE(SUBSTITUTE('Jilla Parishad Income & Expendi'!N4, ",", ""))) -> 339602 | P4: =IF('Jilla Parishad Income & Expendi'!O4="", "", VALUE(SUBSTITUTE('Jilla Parishad Income & Expendi'!O4, ",", ""))) -> 7915.09 | Q4: =IF('Jilla Parishad Income & Expendi'!P4="", "", VALUE(SUBSTITUTE('Jilla Parishad Income & Expendi'!P4, ",", ""))) -> 60334.78 | R4: =IF('Jilla Parishad Income & Expendi'!Q4="", "", VALUE(SUBSTITUTE('Jilla Parishad Income & Expendi'!Q4, ",", ""))) -> 6860.52 | S4: =IF('Jilla Parishad Income & Expendi'!R4="", "", VALUE(SUBSTITUTE('Jilla Parishad Income & Expendi'!R4, ",", ""))) -> 1798.22 | ... AD4: =IF('Jilla Parishad Income & Expendi'!AC4="", "", VALUE(SUBSTITUTE('Jilla Parishad Income & Expendi'!AC4, ",", "")))
A5: Ahmadnagar | B5: =IF('Jilla Parishad Income & Expendi'!B5="", "", VALUE(SUBSTITUTE('Jilla Parishad Income & Expendi'!B5, ",", ""))) -> 2015 | C5: =IF('Jilla Parishad Income & Expendi'!C5="", "", VALUE(SUBSTITUTE('Jilla Parishad Income & Expendi'!C5, ",", ""))) -> 32661 | D5: =IF('Jilla Parishad Income & Expendi'!D5="", "", VALUE(SUBSTITUTE('Jilla Parishad Income & Expendi'!D5, ",", ""))) -> 6378 | E5: =IF('Jilla Parishad Income & Expendi'!E5="", "", VALUE(SUBSTITUTE('Jilla Parishad Income & Expendi'!E5, ",", ""))) | F5: =IF('Jilla Parishad Income & Expendi'!F5="", "", VALUE(SUBSTITUTE('Jilla Parishad Income & Expendi'!F5, ",", ""))) -> 97717 | G5: =IF('Jilla Parishad Income & Expendi'!G5="", "", VALUE(SUBSTITUTE('Jilla Parishad Income & Expendi'!G5, ",", ""))) -> 21646 | H5: =IF('Jilla Parishad Income & Expendi'!H5="", "", VALUE(SUBSTITUTE('Jilla Parishad Income & Expendi'!H5, ",", ""))) -> 30176 | I5: =IF('Jilla Parishad Income & Expendi'!I5="", "", VALUE(SUBSTITUTE('Jilla Parishad Income & Expendi'!I5, ",", ""))) -> 30625 | J5: =IF('Jilla Parishad Income & Expendi'!J5="", "", VALUE(SUBSTITUTE('Jilla Parishad Income & Expendi'!J5, ",", ""))) -> 13357 | K5: =SUM(F5:J5) -> 193521 | L5: =IF('Jilla Parishad Income & Expendi'!K5="", "", VALUE(SUBSTITUTE('Jilla Parishad Income & Expendi'!K5, ",", ""))) -> 0 | M5: =IF('Jilla Parishad Income & Expendi'!L5="", "", VALUE(SUBSTITUTE('Jilla Parishad Income & Expendi'!L5, ",", ""))) -> 52095 | N5: =IF('Jilla Parishad Income & Expendi'!M5="", "", VALUE(SUBSTITUTE('Jilla Parishad Income & Expendi'!M5, ",", ""))) -> 251995 | O5: =IF('Jilla Parishad Income & Expendi'!N5="", "", VALUE(SUBSTITUTE('Jilla Parishad Income & Expendi'!N5, ",", ""))) -> 284655 | P5: =IF('Jilla Parishad Income & Expendi'!O5="", "", VALUE(SUBSTITUTE('Jilla Parishad Income & Expendi'!O5, ",", ""))) -> 13803.81 | Q5: =IF('Jilla Parishad Income & Expendi'!P5="", "", VALUE(SUBSTITUTE('Jilla Parishad Income & Expendi'!P5, ",", ""))) -> 81040.09 | R5: =IF('Jilla Parishad Income & Expendi'!Q5="", "", VALUE(SUBSTITUTE('Jilla Parishad Income & Expendi'!Q5, ",", ""))) -> 6213.06 | S5: =IF('Jilla Parishad Income & Expendi'!R5="", "", VALUE(SUBSTITUTE('Jilla Parishad Income & Expendi'!R5, ",", ""))) -> 602.65 | ... AD5: =IF('Jilla Parishad Income & Expendi'!AC5="", "", VALUE(SUBSTITUTE('Jilla Parishad Income & Expendi'!AC5, ",", "")))
A6: Ahmadnagar | B6: =IF('Jilla Parishad Income & Expendi'!B6="", "", VALUE(SUBSTITUTE('Jilla Parishad Income & Expendi'!B6, ",", ""))) -> 2016 | C6: =IF('Jilla Parishad Income & Expendi'!C6="", "", VALUE(SUBSTITUTE('Jilla Parishad Income & Expendi'!C6, ",", ""))) -> 38745 | D6: =IF('Jilla Parishad Income & Expendi'!D6="", "", VALUE(SUBSTITUTE('Jilla Parishad Income & Expendi'!D6, ",", ""))) -> 5419 | E6: =IF('Jilla Parishad Income & Expendi'!E6="", "", VALUE(SUBSTITUTE('Jilla Parishad Income & Expendi'!E6, ",", ""))) | F6: =IF('Jilla Parishad Income & Expendi'!F6="", "", VALUE(SUBSTITUTE('Jilla Parishad Income & Expendi'!F6, ",", ""))) -> 107363 | G6: =IF('Jilla Parishad Income & Expendi'!G6="", "", VALUE(SUBSTITUTE('Jilla Parishad Income & Expendi'!G6, ",", ""))) -> 17545 | H6: =IF('Jilla Parishad Income & Expendi'!H6="", "", VALUE(SUBSTITUTE('Jilla Parishad Income & Expendi'!H6, ",", ""))) -> 29623 | I6: =IF('Jilla Parishad Income & Expendi'!I6="", "", VALUE(SUBSTITUTE('Jilla Parishad Income & Expendi'!I6, ",", ""))) -> 0 | J6: =IF('Jilla Parishad Income & Expendi'!J6="", "", VALUE(SUBSTITUTE('Jilla Parishad Income & Expendi'!J6, ",", ""))) -> 10069 | K6: =SUM(F6:J6) -> 164600 | L6: =IF('Jilla Parishad Income & Expendi'!K6="", "", VALUE(SUBSTITUTE('Jilla Parishad Income & Expendi'!K6, ",", ""))) -> 92201 | M6: =IF('Jilla Parishad Income & Expendi'!L6="", "", VALUE(SUBSTITUTE('Jilla Parishad Income & Expendi'!L6, ",", ""))) -> 11512 | N6: =IF('Jilla Parishad Income & Expendi'!M6="", "", VALUE(SUBSTITUTE('Jilla Parishad Income & Expendi'!M6, ",", ""))) -> 273730 | O6: =IF('Jilla Parishad Income & Expendi'!N6="", "", VALUE(SUBSTITUTE('Jilla Parishad Income & Expendi'!N6, ",", ""))) -> 312474 | P6: =IF('Jilla Parishad Income & Expendi'!O6="", "", VALUE(SUBSTITUTE('Jilla Parishad Income & Expendi'!O6, ",", ""))) -> 15516.1 | Q6: =IF('Jilla Parishad Income & Expendi'!P6="", "", VALUE(SUBSTITUTE('Jilla Parishad Income & Expendi'!P6, ",", ""))) -> 85281.57 | R6: =IF('Jilla Parishad Income & Expendi'!Q6="", "", VALUE(SUBSTITUTE('Jilla Parishad Income & Expendi'!Q6, ",", ""))) -> 5531.07 | S6: =IF('Jilla Parishad Income & Expendi'!R6="", "", VALUE(SUBSTITUTE('Jilla Parishad Income & Expendi'!R6, ",", ""))) -> 812.41 | ... AD6: =IF('Jilla Parishad Income & Expendi'!AC6="", "", VALUE(SUBSTITUTE('Jilla Parishad Income & Expendi'!AC6, ",", "")))
A7: Ahmadnagar | B7: =IF('Jilla Parishad Income & Expendi'!B7="", "", VALUE(SUBSTITUTE('Jilla Parishad Income & Expendi'!B7, ",", ""))) -> 2017 | C7: =IF('Jilla Parishad Income & Expendi'!C7="", "", VALUE(SUBSTITUTE('Jilla Parishad Income & Expendi'!C7, ",", ""))) -> 40707 | D7: =IF('Jilla Parishad Income & Expendi'!D7="", "", VALUE(SUBSTITUTE('Jilla Parishad Income & Expendi'!D7, ",", ""))) -> 2767 | E7: =IF('Jilla Parishad Income & Expendi'!E7="", "", VALUE(SUBSTITUTE('Jilla Parishad Income & Expendi'!E7, ",", ""))) | F7: =IF('Jilla Parishad Income & Expendi'!F7="", "", VALUE(SUBSTITUTE('Jilla Parishad Income & Expendi'!F7, ",", ""))) -> 39733 | G7: =IF('Jilla Parishad Income & Expendi'!G7="", "", VALUE(SUBSTITUTE('Jilla Parishad Income & Expendi'!G7, ",", ""))) -> 17347 | H7: =IF('Jilla Parishad Income & Expendi'!H7="", "", VALUE(SUBSTITUTE('Jilla Parishad Income & Expendi'!H7, ",", ""))) -> 110296 | I7: =IF('Jilla Parishad Income & Expendi'!I7="", "", VALUE(SUBSTITUTE('Jilla Parishad Income & Expendi'!I7, ",", ""))) -> 0 | J7: =IF('Jilla Parishad Income & Expendi'!J7="", "", VALUE(SUBSTITUTE('Jilla Parishad Income & Expendi'!J7, ",", ""))) -> 5567 | K7: =SUM(F7:J7) -> 172943 | L7: =IF('Jilla Parishad Income & Expendi'!K7="", "", VALUE(SUBSTITUTE('Jilla Parishad Income & Expendi'!K7, ",", ""))) -> 70330 | M7: =IF('Jilla Parishad Income & Expendi'!L7="", "", VALUE(SUBSTITUTE('Jilla Parishad Income & Expendi'!L7, ",", ""))) -> 16051 | N7: =IF('Jilla Parishad Income & Expendi'!M7="", "", VALUE(SUBSTITUTE('Jilla Parishad Income & Expendi'!M7, ",", ""))) -> 262090 | O7: =IF('Jilla Parishad Income & Expendi'!N7="", "", VALUE(SUBSTITUTE('Jilla Parishad Income & Expendi'!N7, ",", ""))) -> 302797 | P7: =IF('Jilla Parishad Income & Expendi'!O7="", "", VALUE(SUBSTITUTE('Jilla Parishad Income & Expendi'!O7, ",", ""))) -> 15278.95 | Q7: =IF('Jilla Parishad Income & Expendi'!P7="", "", VALUE(SUBSTITUTE('Jilla Parishad Income & Expendi'!P7, ",", ""))) -> 89993.68 | R7: =IF('Jilla Parishad Income & Expendi'!Q7="", "", VALUE(SUBSTITUTE('Jilla Parishad Income & Expendi'!Q7, ",", ""))) -> 1908.22 | S7: =IF('Jilla Parishad Income & Expendi'!R7="", "", VALUE(SUBSTITUTE('Jilla Parishad Income & Expendi'!R7, ",", ""))) -> 911.33 | ... AD7: =IF('Jilla Parishad Income & Expendi'!AC7="", "", VALUE(SUBSTITUTE('Jilla Parishad Income & Expendi'!AC7, ",", "")))
A8: Ahmadnagar | B8: =IF('Jilla Parishad Income & Expendi'!B8="", "", VALUE(SUBSTITUTE('Jilla Parishad Income & Expendi'!B8, ",", ""))) -> 2018 | C8: =IF('Jilla Parishad Income & Expendi'!C8="", "", VALUE(SUBSTITUTE('Jilla Parishad Income & Expendi'!C8, ",", ""))) -> 46861 | D8: =IF('Jilla Parishad Income & Expendi'!D8="", "", VALUE(SUBSTITUTE('Jilla Parishad Income & Expendi'!D8, ",", ""))) -> 2994 | E8: =IF('Jilla Parishad Income & Expendi'!E8="", "", VALUE(SUBSTITUTE('Jilla Parishad Income & Expendi'!E8, ",", ""))) | F8: =IF('Jilla Parishad Income & Expendi'!F8="", "", VALUE(SUBSTITUTE('Jilla Parishad Income & Expendi'!F8, ",", ""))) -> 30528 | G8: =IF('Jilla Parishad Income & Expendi'!G8="", "", VALUE(SUBSTITUTE('Jilla Parishad Income & Expendi'!G8, ",", ""))) -> 18328 | H8: =IF('Jilla Parishad Income & Expendi'!H8="", "", VALUE(SUBSTITUTE('Jilla Parishad Income & Expendi'!H8, ",", ""))) -> 120617 | I8: =IF('Jilla Parishad Income & Expendi'!I8="", "", VALUE(SUBSTITUTE('Jilla Parishad Income & Expendi'!I8, ",", ""))) -> 0 | J8: =IF('Jilla Parishad Income & Expendi'!J8="", "", VALUE(SUBSTITUTE('Jilla Parishad Income & Expendi'!J8, ",", ""))) -> 7570 | K8: =SUM(F8:J8) -> 177043 | L8: =IF('Jilla Parishad Income & Expendi'!K8="", "", VALUE(SUBSTITUTE('Jilla Parishad Income & Expendi'!K8, ",", ""))) -> 53018 | M8: =IF('Jilla Parishad Income & Expendi'!L8="", "", VALUE(SUBSTITUTE('Jilla Parishad Income & Expendi'!L8, ",", ""))) -> 71772 | N8: =IF('Jilla Parishad Income & Expendi'!M8="", "", VALUE(SUBSTITUTE('Jilla Parishad Income & Expendi'!M8, ",", ""))) -> 304826 | O8: =IF('Jilla Parishad Income & Expendi'!N8="", "", VALUE(SUBSTITUTE('Jilla Parishad Income & Expendi'!N8, ",", ""))) -> 351687 | P8: =IF('Jilla Parishad Income & Expendi'!O8="", "", VALUE(SUBSTITUTE('Jilla Parishad Income & Expendi'!O8, ",", ""))) -> 18498.86 | Q8: =IF('Jilla Parishad Income & Expendi'!P8="", "", VALUE(SUBSTITUTE('Jilla Parishad Income & Expendi'!P8, ",", ""))) -> 95606.74 | R8: =IF('Jilla Parishad Income & Expendi'!Q8="", "", VALUE(SUBSTITUTE('Jilla Parishad Income & Expendi'!Q8, ",", ""))) -> 6472.43 | S8: =IF('Jilla Parishad Income & Expendi'!R8="", "", VALUE(SUBSTITUTE('Jilla Parishad Income & Expendi'!R8, ",", ""))) -> 3670.21 | ... AD8: =IF('Jilla Parishad Income & Expendi'!AC8="", "", VALUE(SUBSTITUTE('Jilla Parishad Income & Expendi'!AC8, ",", "")))
A9: Ahmadnagar | B9: =IF('Jilla Parishad Income & Expendi'!B9="", "", VALUE(SUBSTITUTE('Jilla Parishad Income & Expendi'!B9, ",", ""))) -> 2019 | C9: =IF('Jilla Parishad Income & Expendi'!C9="", "", VALUE(SUBSTITUTE('Jilla Parishad Income & Expendi'!C9, ",", ""))) -> 46861 | D9: =IF('Jilla Parishad Income & Expendi'!D9="", "", VALUE(SUBSTITUTE('Jilla Parishad Income & Expendi'!D9, ",", ""))) -> 2165 | E9: =IF('Jilla Parishad Income & Expendi'!E9="", "", VALUE(SUBSTITUTE('Jilla Parishad Income & Expendi'!E9, ",", ""))) | F9: =IF('Jilla Parishad Income & Expendi'!F9="", "", VALUE(SUBSTITUTE('Jilla Parishad Income & Expendi'!F9, ",", ""))) -> 28757 | G9: =IF('Jilla Parishad Income & Expendi'!G9="", "", VALUE(SUBSTITUTE('Jilla Parishad Income & Expendi'!G9, ",", ""))) -> 24892 | H9: =IF('Jilla Parishad Income & Expendi'!H9="", "", VALUE(SUBSTITUTE('Jilla Parishad Income & Expendi'!H9, ",", ""))) -> 166370 | I9: =IF('Jilla Parishad Income & Expendi'!I9="", "", VALUE(SUBSTITUTE('Jilla Parishad Income & Expendi'!I9, ",", ""))) -> 0 | J9: =IF('Jilla Parishad Income & Expendi'!J9="", "", VALUE(SUBSTITUTE('Jilla Parishad Income & Expendi'!J9, ",", ""))) -> 8956 | K9: =SUM(F9:J9) -> 228975 | L9: =IF('Jilla Parishad Income & Expendi'!K9="", "", VALUE(SUBSTITUTE('Jilla Parishad Income & Expendi'!K9, ",", ""))) -> 58248 | M9: =IF('Jilla Parishad Income & Expendi'!L9="", "", VALUE(SUBSTITUTE('Jilla Parishad Income & Expendi'!L9, ",", ""))) -> 50566 | N9: =IF('Jilla Parishad Income & Expendi'!M9="", "", VALUE(SUBSTITUTE('Jilla Parishad Income & Expendi'!M9, ",", ""))) -> 339954 | O9: =IF('Jilla Parishad Income & Expendi'!N9="", "", VALUE(SUBSTITUTE('Jilla Parishad Income & Expendi'!N9, ",", ""))) -> 386815 | P9: =IF('Jilla Parishad Income & Expendi'!O9="", "", VALUE(SUBSTITUTE('Jilla Parishad Income & Expendi'!O9, ",", ""))) -> 24180.49 | Q9: =IF('Jilla Parishad Income & Expendi'!P9="", "", VALUE(SUBSTITUTE('Jilla Parishad Income & Expendi'!P9, ",", ""))) -> 122784.95 | R9: =IF('Jilla Parishad Income & Expendi'!Q9="", "", VALUE(SUBSTITUTE('Jilla Parishad Income & Expendi'!Q9, ",", ""))) -> 9489.65 | S9: =IF('Jilla Parishad Income & Expendi'!R9="", "", VALUE(SUBSTITUTE('Jilla Parishad Income & Expendi'!R9, ",", ""))) -> 4062.07 | ... AD9: =IF('Jilla Parishad Income & Expendi'!AC9="", "", VALUE(SUBSTITUTE('Jilla Parishad Income & Expendi'!AC9, ",", "")))
A10: Ahmadnagar | B10: =IF('Jilla Parishad Income & Expendi'!B10="", "", VALUE(SUBSTITUTE('Jilla Parishad Income & Expendi'!B10, ",", ""))) -> 2020 | C10: =IF('Jilla Parishad Income & Expendi'!C10="", "", VALUE(SUBSTITUTE('Jilla Parishad Income & Expendi'!C10, ",", ""))) -> 45711 | D10: =IF('Jilla Parishad Income & Expendi'!D10="", "", VALUE(SUBSTITUTE('Jilla Parishad Income & Expendi'!D10, ",", ""))) -> 3247 | E10: =IF('Jilla Parishad Income & Expendi'!E10="", "", VALUE(SUBSTITUTE('Jilla Parishad Income & Expendi'!E10, ",", ""))) | F10: =IF('Jilla Parishad Income & Expendi'!F10="", "", VALUE(SUBSTITUTE('Jilla Parishad Income & Expendi'!F10, ",", ""))) -> 34450 | G10: =IF('Jilla Parishad Income & Expendi'!G10="", "", VALUE(SUBSTITUTE('Jilla Parishad Income & Expendi'!G10, ",", ""))) -> 122385 | H10: =IF('Jilla Parishad Income & Expendi'!H10="", "", VALUE(SUBSTITUTE('Jilla Parishad Income & Expendi'!H10, ",", ""))) -> 57698 | I10: =IF('Jilla Parishad Income & Expendi'!I10="", "", VALUE(SUBSTITUTE('Jilla Parishad Income & Expendi'!I10, ",", ""))) -> 0 | J10: =IF('Jilla Parishad Income & Expendi'!J10="", "", VALUE(SUBSTITUTE('Jilla Parishad Income & Expendi'!J10, ",", ""))) -> 9071 | K10: =SUM(F10:J10) -> 223604 | L10: =IF('Jilla Parishad Income & Expendi'!K10="", "", VALUE(SUBSTITUTE('Jilla Parishad Income & Expendi'!K10, ",", ""))) -> 49700 | M10: =IF('Jilla Parishad Income & Expendi'!L10="", "", VALUE(SUBSTITUTE('Jilla Parishad Income & Expendi'!L10, ",", ""))) -> 49881 | N10: =IF('Jilla Parishad Income & Expendi'!M10="", "", VALUE(SUBSTITUTE('Jilla Parishad Income & Expendi'!M10, ",", ""))) -> 326433 | O10: =IF('Jilla Parishad Income & Expendi'!N10="", "", VALUE(SUBSTITUTE('Jilla Parishad Income & Expendi'!N10, ",", ""))) -> 372144 | P10: =IF('Jilla Parishad Income & Expendi'!O10="", "", VALUE(SUBSTITUTE('Jilla Parishad Income & Expendi'!O10, ",", ""))) -> 20813.44 | Q10: =IF('Jilla Parishad Income & Expendi'!P10="", "", VALUE(SUBSTITUTE('Jilla Parishad Income & Expendi'!P10, ",", ""))) -> 117956.45 | R10: =IF('Jilla Parishad Income & Expendi'!Q10="", "", VALUE(SUBSTITUTE('Jilla Parishad Income & Expendi'!Q10, ",", ""))) -> 5810.9 | S10: =IF('Jilla Parishad Income & Expendi'!R10="", "", VALUE(SUBSTITUTE('Jilla Parishad Income & Expendi'!R10, ",", ""))) -> 1908.84 | ... AD10: =IF('Jilla Parishad Income & Expendi'!AC10="", "", VALUE(SUBSTITUTE('Jilla Parishad Income & Expendi'!AC10, ",", "")))
A11: Akola | B11: =IF('Jilla Parishad Income & Expendi'!B11="", "", VALUE(SUBSTITUTE('Jilla Parishad Income & Expendi'!B11, ",", ""))) -> 2012 | C11: =IF('Jilla Parishad Income & Expendi'!C11="", "", VALUE(SUBSTITUTE('Jilla Parishad Income & Expendi'!C11, ",", ""))) -> 10988.41 | D11: =IF('Jilla Parishad Income & Expendi'!D11="", "", VALUE(SUBSTITUTE('Jilla Parishad Income & Expendi'!D11, ",", ""))) -> 0 | E11: =IF('Jilla Parishad Income & Expendi'!E11="", "", VALUE(SUBSTITUTE('Jilla Parishad Income & Expendi'!E11, ",", ""))) | F11: =IF('Jilla Parishad Income & Expendi'!F11="", "", VALUE(SUBSTITUTE('Jilla Parishad Income & Expendi'!F11, ",", ""))) -> 27017.6 | G11: =IF('Jilla Parishad Income & Expendi'!G11="", "", VALUE(SUBSTITUTE('Jilla Parishad Income & Expendi'!G11, ",", ""))) -> 4726.93 | H11: =IF('Jilla Parishad Income & Expendi'!H11="", "", VALUE(SUBSTITUTE('Jilla Parishad Income & Expendi'!H11, ",", ""))) -> 12999.99 | I11: =IF('Jilla Parishad Income & Expendi'!I11="", "", VALUE(SUBSTITUTE('Jilla Parishad Income & Expendi'!I11, ",", ""))) -> 179.36 | J11: =IF('Jilla Parishad Income & Expendi'!J11="", "", VALUE(SUBSTITUTE('Jilla Parishad Income & Expendi'!J11, ",", ""))) -> 2613.12 | K11: =SUM(F11:J11) -> 47537 | L11: =IF('Jilla Parishad Income & Expendi'!K11="", "", VALUE(SUBSTITUTE('Jilla Parishad Income & Expendi'!K11, ",", ""))) -> 0 | M11: =IF('Jilla Parishad Income & Expendi'!L11="", "", VALUE(SUBSTITUTE('Jilla Parishad Income & Expendi'!L11, ",", ""))) -> 50063.4 | N11: =IF('Jilla Parishad Income & Expendi'!M11="", "", VALUE(SUBSTITUTE('Jilla Parishad Income & Expendi'!M11, ",", ""))) -> 97600 | O11: =IF('Jilla Parishad Income & Expendi'!N11="", "", VALUE(SUBSTITUTE('Jilla Parishad Income & Expendi'!N11, ",", ""))) -> 108589 | P11: =IF('Jilla Parishad Income & Expendi'!O11="", "", VALUE(SUBSTITUTE('Jilla Parishad Income & Expendi'!O11, ",", ""))) -> 1976.1 | Q11: =IF('Jilla Parishad Income & Expendi'!P11="", "", VALUE(SUBSTITUTE('Jilla Parishad Income & Expendi'!P11, ",", ""))) -> 24250.41 | R11: =IF('Jilla Parishad Income & Expendi'!Q11="", "", VALUE(SUBSTITUTE('Jilla Parishad Income & Expendi'!Q11, ",", ""))) -> 2540.9 | S11: =IF('Jilla Parishad Income & Expendi'!R11="", "", VALUE(SUBSTITUTE('Jilla Parishad Income & Expendi'!R11, ",", ""))) -> 601.23 | ... AD11: =IF('Jilla Parishad Income & Expendi'!AC11="", "", VALUE(SUBSTITUTE('Jilla Parishad Income & Expendi'!AC11, ",", "")))
A12: Akola | B12: =IF('Jilla Parishad Income & Expendi'!B12="", "", VALUE(SUBSTITUTE('Jilla Parishad Income & Expendi'!B12, ",", ""))) -> 2013 | C12: =IF('Jilla Parishad Income & Expendi'!C12="", "", VALUE(SUBSTITUTE('Jilla Parishad Income & Expendi'!C12, ",", ""))) -> 13073.92 | D12: =IF('Jilla Parishad Income & Expendi'!D12="", "", VALUE(SUBSTITUTE('Jilla Parishad Income & Expendi'!D12, ",", ""))) -> 3920.53 | E12: =IF('Jilla Parishad Income & Expendi'!E12="", "", VALUE(SUBSTITUTE('Jilla Parishad Income & Expendi'!E12, ",", ""))) | F12: =IF('Jilla Parishad Income & Expendi'!F12="", "", VALUE(SUBSTITUTE('Jilla Parishad Income & Expendi'!F12, ",", ""))) -> 28212.05 | G12: =IF('Jilla Parishad Income & Expendi'!G12="", "", VALUE(SUBSTITUTE('Jilla Parishad Income & Expendi'!G12, ",", ""))) -> 5062.06 | H12: =IF('Jilla Parishad Income & Expendi'!H12="", "", VALUE(SUBSTITUTE('Jilla Parishad Income & Expendi'!H12, ",", ""))) -> 11451.46 | I12: =IF('Jilla Parishad Income & Expendi'!I12="", "", VALUE(SUBSTITUTE('Jilla Parishad Income & Expendi'!I12, ",", ""))) -> 11.36 | J12: =IF('Jilla Parishad Income & Expendi'!J12="", "", VALUE(SUBSTITUTE('Jilla Parishad Income & Expendi'!J12, ",", ""))) -> 2680.86 | K12: =SUM(F12:J12) -> 47417.79 | L12: =IF('Jilla Parishad Income & Expendi'!K12="", "", VALUE(SUBSTITUTE('Jilla Parishad Income & Expendi'!K12, ",", ""))) -> 131.13 | M12: =IF('Jilla Parishad Income & Expendi'!L12="", "", VALUE(SUBSTITUTE('Jilla Parishad Income & Expendi'!L12, ",", ""))) -> 49579.17 | N12: =IF('Jilla Parishad Income & Expendi'!M12="", "", VALUE(SUBSTITUTE('Jilla Parishad Income & Expendi'!M12, ",", ""))) -> 101049 | O12: =IF('Jilla Parishad Income & Expendi'!N12="", "", VALUE(SUBSTITUTE('Jilla Parishad Income & Expendi'!N12, ",", ""))) -> 114123 | P12: =IF('Jilla Parishad Income & Expendi'!O12="", "", VALUE(SUBSTITUTE('Jilla Parishad Income & Expendi'!O12, ",", ""))) -> 2230.21 | Q12: =IF('Jilla Parishad Income & Expendi'!P12="", "", VALUE(SUBSTITUTE('Jilla Parishad Income & Expendi'!P12, ",", ""))) -> 25881.29 | R12: =IF('Jilla Parishad Income & Expendi'!Q12="", "", VALUE(SUBSTITUTE('Jilla Parishad Income & Expendi'!Q12, ",", ""))) -> 2155.08 | S12: =IF('Jilla Parishad Income & Expendi'!R12="", "", VALUE(SUBSTITUTE('Jilla Parishad Income & Expendi'!R12, ",", ""))) -> 416 | ... AD12: =IF('Jilla Parishad Income & Expendi'!AC12="", "", VALUE(SUBSTITUTE('Jilla Parishad Income & Expendi'!AC12, ",", "")))
A13: Akola | B13: =IF('Jilla Parishad Income & Expendi'!B13="", "", VALUE(SUBSTITUTE('Jilla Parishad Income & Expendi'!B13, ",", ""))) -> 2014 | C13: =IF('Jilla Parishad Income & Expendi'!C13="", "", VALUE(SUBSTITUTE('Jilla Parishad Income & Expendi'!C13, ",", ""))) -> 19039.92 | D13: =IF('Jilla Parishad Income & Expendi'!D13="", "", VALUE(SUBSTITUTE('Jilla Parishad Income & Expendi'!D13, ",", ""))) -> 3948.69 | E13: =IF('Jilla Parishad Income & Expendi'!E13="", "", VALUE(SUBSTITUTE('Jilla Parishad Income & Expendi'!E13, ",", ""))) | F13: =IF('Jilla Parishad Income & Expendi'!F13="", "", VALUE(SUBSTITUTE('Jilla Parishad Income & Expendi'!F13, ",", ""))) -> 27867.28 | G13: =IF('Jilla Parishad Income & Expendi'!G13="", "", VALUE(SUBSTITUTE('Jilla Parishad Income & Expendi'!G13, ",", ""))) -> 9175.73 | H13: =IF('Jilla Parishad Income & Expendi'!H13="", "", VALUE(SUBSTITUTE('Jilla Parishad Income & Expendi'!H13, ",", ""))) -> 13058.25 | I13: =IF('Jilla Parishad Income & Expendi'!I13="", "", VALUE(SUBSTITUTE('Jilla Parishad Income & Expendi'!I13, ",", ""))) -> 45.5 | J13: =IF('Jilla Parishad Income & Expendi'!J13="", "", VALUE(SUBSTITUTE('Jilla Parishad Income & Expendi'!J13, ",", ""))) -> 3738.17 | K13: =SUM(F13:J13) -> 53884.93 | L13: =IF('Jilla Parishad Income & Expendi'!K13="", "", VALUE(SUBSTITUTE('Jilla Parishad Income & Expendi'!K13, ",", ""))) -> 0 | M13: =IF('Jilla Parishad Income & Expendi'!L13="", "", VALUE(SUBSTITUTE('Jilla Parishad Income & Expendi'!L13, ",", ""))) -> 51549.49 | N13: =IF('Jilla Parishad Income & Expendi'!M13="", "", VALUE(SUBSTITUTE('Jilla Parishad Income & Expendi'!M13, ",", ""))) -> 109383 | O13: =IF('Jilla Parishad Income & Expendi'!N13="", "", VALUE(SUBSTITUTE('Jilla Parishad Income & Expendi'!N13, ",", ""))) -> 128423 | P13: =IF('Jilla Parishad Income & Expendi'!O13="", "", VALUE(SUBSTITUTE('Jilla Parishad Income & Expendi'!O13, ",", ""))) -> 5564.49 | Q13: =IF('Jilla Parishad Income & Expendi'!P13="", "", VALUE(SUBSTITUTE('Jilla Parishad Income & Expendi'!P13, ",", ""))) -> 26948.05 | R13: =IF('Jilla Parishad Income & Expendi'!Q13="", "", VALUE(SUBSTITUTE('Jilla Parishad Income & Expendi'!Q13, ",", ""))) -> 3428.23 | S13: =IF('Jilla Parishad Income & Expendi'!R13="", "", VALUE(SUBSTITUTE('Jilla Parishad Income & Expendi'!R13, ",", ""))) -> 935.49 | ... AD13: =IF('Jilla Parishad Income & Expendi'!AC13="", "", VALUE(SUBSTITUTE('Jilla Parishad Income & Expendi'!AC13, ",", "")))
... A30: Amravati | B30: =IF('Jilla Parishad Income & Expendi'!B30="", "", VALUE(SUBSTITUTE('Jilla Parishad Income & Expendi'!B30, ",", ""))) -> 2021 | C30: =IF('Jilla Parishad Income & Expendi'!C30="", "", VALUE(SUBSTITUTE('Jilla Parishad Income & Expendi'!C30, ",", ""))) -> 48658.07 | D30: =IF('Jilla Parishad Income & Expendi'!D30="", "", VALUE(SUBSTITUTE('Jilla Parishad Income & Expendi'!D30, ",", ""))) -> 1843.65 | E30: =IF('Jilla Parishad Income & Expendi'!E30="", "", VALUE(SUBSTITUTE('Jilla Parishad Income & Expendi'!E30, ",", ""))) | F30: =IF('Jilla Parishad Income & Expendi'!F30="", "", VALUE(SUBSTITUTE('Jilla Parishad Income & Expendi'!F30, ",", ""))) -> 0 | G30: =IF('Jilla Parishad Income & Expendi'!G30="", "", VALUE(SUBSTITUTE('Jilla Parishad Income & Expendi'!G30, ",", ""))) -> 111488.48 | H30: =IF('Jilla Parishad Income & Expendi'!H30="", "", VALUE(SUBSTITUTE('Jilla Parishad Income & Expendi'!H30, ",", ""))) -> 29389.98 | I30: =IF('Jilla Parishad Income & Expendi'!I30="", "", VALUE(SUBSTITUTE('Jilla Parishad Income & Expendi'!I30, ",", ""))) -> 0 | J30: =IF('Jilla Parishad Income & Expendi'!J30="", "", VALUE(SUBSTITUTE('Jilla Parishad Income & Expendi'!J30, ",", ""))) -> 7981.36 | K30: =SUM(F30:J30) -> 148859.82 | L30: =IF('Jilla Parishad Income & Expendi'!K30="", "", VALUE(SUBSTITUTE('Jilla Parishad Income & Expendi'!K30, ",", ""))) -> 0 | M30: =IF('Jilla Parishad Income & Expendi'!L30="", "", VALUE(SUBSTITUTE('Jilla Parishad Income & Expendi'!L30, ",", ""))) -> 1862.14 | N30: =IF('Jilla Parishad Income & Expendi'!M30="", "", VALUE(SUBSTITUTE('Jilla Parishad Income & Expendi'!M30, ",", ""))) -> 152566 | O30: =IF('Jilla Parishad Income & Expendi'!N30="", "", VALUE(SUBSTITUTE('Jilla Parishad Income & Expendi'!N30, ",", ""))) -> 201224 | P30: =IF('Jilla Parishad Income & Expendi'!O30="", "", VALUE(SUBSTITUTE('Jilla Parishad Income & Expendi'!O30, ",", ""))) -> 309.1 | Q30: =IF('Jilla Parishad Income & Expendi'!P30="", "", VALUE(SUBSTITUTE('Jilla Parishad Income & Expendi'!P30, ",", ""))) -> 75026.73 | R30: =IF('Jilla Parishad Income & Expendi'!Q30="", "", VALUE(SUBSTITUTE('Jilla Parishad Income & Expendi'!Q30, ",", ""))) -> 13355.06 | S30: =IF('Jilla Parishad Income & Expendi'!R30="", "", VALUE(SUBSTITUTE('Jilla Parishad Income & Expendi'!R30, ",", ""))) -> 1250.16 | ... AD30: =IF('Jilla Parishad Income & Expendi'!AC30="", "", VALUE(SUBSTITUTE('Jilla Parishad Income & Expendi'!AC30, ",", "")))
A31: Bhandara | B31: =IF('Jilla Parishad Income & Expendi'!B31="", "", VALUE(SUBSTITUTE('Jilla Parishad Income & Expendi'!B31, ",", ""))) -> 2012 | C31: =IF('Jilla Parishad Income & Expendi'!C31="", "", VALUE(SUBSTITUTE('Jilla Parishad Income & Expendi'!C31, ",", ""))) -> 13642 | D31: =IF('Jilla Parishad Income & Expendi'!D31="", "", VALUE(SUBSTITUTE('Jilla Parishad Income & Expendi'!D31, ",", ""))) -> 0 | E31: =IF('Jilla Parishad Income & Expendi'!E31="", "", VALUE(SUBSTITUTE('Jilla Parishad Income & Expendi'!E31, ",", ""))) | F31: =IF('Jilla Parishad Income & Expendi'!F31="", "", VALUE(SUBSTITUTE('Jilla Parishad Income & Expendi'!F31, ",", ""))) -> 41775 | G31: =IF('Jilla Parishad Income & Expendi'!G31="", "", VALUE(SUBSTITUTE('Jilla Parishad Income & Expendi'!G31, ",", ""))) | H31: =IF('Jilla Parishad Income & Expendi'!H31="", "", VALUE(SUBSTITUTE('Jilla Parishad Income & Expendi'!H31, ",", ""))) | I31: =IF('Jilla Parishad Income & Expendi'!I31="", "", VALUE(SUBSTITUTE('Jilla Parishad Income & Expendi'!I31, ",", ""))) | J31: =IF('Jilla Parishad Income & Expendi'!J31="", "", VALUE(SUBSTITUTE('Jilla Parishad Income & Expendi'!J31, ",", ""))) | K31: =SUM(F31:J31) -> 41775 | L31: =IF('Jilla Parishad Income & Expendi'!K31="", "", VALUE(SUBSTITUTE('Jilla Parishad Income & Expendi'!K31, ",", ""))) -> 587 | M31: =IF('Jilla Parishad Income & Expendi'!L31="", "", VALUE(SUBSTITUTE('Jilla Parishad Income & Expendi'!L31, ",", ""))) -> 2620 | P31: =IF('Jilla Parishad Income & Expendi'!O31="", "", VALUE(SUBSTITUTE('Jilla Parishad Income & Expendi'!O31, ",", ""))) -> 1805 | Q31: =IF('Jilla Parishad Income & Expendi'!P31="", "", VALUE(SUBSTITUTE('Jilla Parishad Income & Expendi'!P31, ",", ""))) -> 19482 | R31: =IF('Jilla Parishad Income & Expendi'!Q31="", "", VALUE(SUBSTITUTE('Jilla Parishad Income & Expendi'!Q31, ",", ""))) -> 1954 | S31: =IF('Jilla Parishad Income & Expendi'!R31="", "", VALUE(SUBSTITUTE('Jilla Parishad Income & Expendi'!R31, ",", ""))) -> 1377 | T31: =IF('Jilla Parishad Income & Expendi'!S31="", "", VALUE(SUBSTITUTE('Jilla Parishad Income & Expendi'!S31, ",", ""))) -> 431 | U31: =IF('Jilla Parishad Income & Expendi'!T31="", "", VALUE(SUBSTITUTE('Jilla Parishad Income & Expendi'!T31, ",", ""))) -> 343 | V31: =IF('Jilla Parishad Income & Expendi'!U31="", "", VALUE(SUBSTITUTE('Jilla Parishad Income & Expendi'!U31, ",", ""))) -> 22 | W31: =IF('Jilla Parishad Income & Expendi'!V31="", "", VALUE(SUBSTITUTE('Jilla Parishad Income & Expendi'!V31, ",", ""))) -> 2437 | ... AD31: =IF('Jilla Parishad Income & Expendi'!AC31="", "", VALUE(SUBSTITUTE('Jilla Parishad Income & Expendi'!AC31, ",", "")))
A32: Bhandara | B32: =IF('Jilla Parishad Income & Expendi'!B32="", "", VALUE(SUBSTITUTE('Jilla Parishad Income & Expendi'!B32, ",", ""))) -> 2013 | C32: =IF('Jilla Parishad Income & Expendi'!C32="", "", VALUE(SUBSTITUTE('Jilla Parishad Income & Expendi'!C32, ",", ""))) -> 17434 | D32: =IF('Jilla Parishad Income & Expendi'!D32="", "", VALUE(SUBSTITUTE('Jilla Parishad Income & Expendi'!D32, ",", ""))) -> 0 | E32: =IF('Jilla Parishad Income & Expendi'!E32="", "", VALUE(SUBSTITUTE('Jilla Parishad Income & Expendi'!E32, ",", ""))) | F32: =IF('Jilla Parishad Income & Expendi'!F32="", "", VALUE(SUBSTITUTE('Jilla Parishad Income & Expendi'!F32, ",", ""))) -> 44957 | G32: =IF('Jilla Parishad Income & Expendi'!G32="", "", VALUE(SUBSTITUTE('Jilla Parishad Income & Expendi'!G32, ",", ""))) | H32: =IF('Jilla Parishad Income & Expendi'!H32="", "", VALUE(SUBSTITUTE('Jilla Parishad Income & Expendi'!H32, ",", ""))) | I32: =IF('Jilla Parishad Income & Expendi'!I32="", "", VALUE(SUBSTITUTE('Jilla Parishad Income & Expendi'!I32, ",", ""))) | J32: =IF('Jilla Parishad Income & Expendi'!J32="", "", VALUE(SUBSTITUTE('Jilla Parishad Income & Expendi'!J32, ",", ""))) | K32: =SUM(F32:J32) -> 44957 | L32: =IF('Jilla Parishad Income & Expendi'!K32="", "", VALUE(SUBSTITUTE('Jilla Parishad Income & Expendi'!K32, ",", ""))) -> 495 | M32: =IF('Jilla Parishad Income & Expendi'!L32="", "", VALUE(SUBSTITUTE('Jilla Parishad Income & Expendi'!L32, ",", ""))) -> 1908 | P32: =IF('Jilla Parishad Income & Expendi'!O32="", "", VALUE(SUBSTITUTE('Jilla Parishad Income & Expendi'!O32, ",", ""))) -> 4873 | Q32: =IF('Jilla Parishad Income & Expendi'!P32="", "", VALUE(SUBSTITUTE('Jilla Parishad Income & Expendi'!P32, ",", ""))) -> 23505 | R32: =IF('Jilla Parishad Income & Expendi'!Q32="", "", VALUE(SUBSTITUTE('Jilla Parishad Income & Expendi'!Q32, ",", ""))) -> 3023 | S32: =IF('Jilla Parishad Income & Expendi'!R32="", "", VALUE(SUBSTITUTE('Jilla Parishad Income & Expendi'!R32, ",", ""))) -> 1140 | T32: =IF('Jilla Parishad Income & Expendi'!S32="", "", VALUE(SUBSTITUTE('Jilla Parishad Income & Expendi'!S32, ",", ""))) -> 554 | U32: =IF('Jilla Parishad Income & Expendi'!T32="", "", VALUE(SUBSTITUTE('Jilla Parishad Income & Expendi'!T32, ",", ""))) -> 583 | V32: =IF('Jilla Parishad Income & Expendi'!U32="", "", VALUE(SUBSTITUTE('Jilla Parishad Income & Expendi'!U32, ",", ""))) -> 13 | W32: =IF('Jilla Parishad Income & Expendi'!V32="", "", VALUE(SUBSTITUTE('Jilla Parishad Income & Expendi'!V32, ",", ""))) -> 3373 | ... AD32: =IF('Jilla Parishad Income & Expendi'!AC32="", "", VALUE(SUBSTITUTE('Jilla Parishad Income & Expendi'!AC32, ",", "")))
A33: Bhandara | B33: =IF('Jilla Parishad Income & Expendi'!B33="", "", VALUE(SUBSTITUTE('Jilla Parishad Income & Expendi'!B33, ",", ""))) -> 2014 | C33: =IF('Jilla Parishad Income & Expendi'!C33="", "", VALUE(SUBSTITUTE('Jilla Parishad Income & Expendi'!C33, ",", ""))) -> 14812 | D33: =IF('Jilla Parishad Income & Expendi'!D33="", "", VALUE(SUBSTITUTE('Jilla Parishad Income & Expendi'!D33, ",", ""))) -> 0 | E33: =IF('Jilla Parishad Income & Expendi'!E33="", "", VALUE(SUBSTITUTE('Jilla Parishad Income & Expendi'!E33, ",", ""))) | F33: =IF('Jilla Parishad Income & Expendi'!F33="", "", VALUE(SUBSTITUTE('Jilla Parishad Income & Expendi'!F33, ",", ""))) -> 49800 | G33: =IF('Jilla Parishad Income & Expendi'!G33="", "", VALUE(SUBSTITUTE('Jilla Parishad Income & Expendi'!G33, ",", ""))) | H33: =IF('Jilla Parishad Income & Expendi'!H33="", "", VALUE(SUBSTITUTE('Jilla Parishad Income & Expendi'!H33, ",", ""))) | I33: =IF('Jilla Parishad Income & Expendi'!I33="", "", VALUE(SUBSTITUTE('Jilla Parishad Income & Expendi'!I33, ",", ""))) | J33: =IF('Jilla Parishad Income & Expendi'!J33="", "", VALUE(SUBSTITUTE('Jilla Parishad Income & Expendi'!J33, ",", ""))) | K33: =SUM(F33:J33) -> 49800 | L33: =IF('Jilla Parishad Income & Expendi'!K33="", "", VALUE(SUBSTITUTE('Jilla Parishad Income & Expendi'!K33, ",", ""))) -> 799 | M33: =IF('Jilla Parishad Income & Expendi'!L33="", "", VALUE(SUBSTITUTE('Jilla Parishad Income & Expendi'!L33, ",", ""))) -> 2420 | P33: =IF('Jilla Parishad Income & Expendi'!O33="", "", VALUE(SUBSTITUTE('Jilla Parishad Income & Expendi'!O33, ",", ""))) -> 5467 | Q33: =IF('Jilla Parishad Income & Expendi'!P33="", "", VALUE(SUBSTITUTE('Jilla Parishad Income & Expendi'!P33, ",", ""))) -> 24748 | R33: =IF('Jilla Parishad Income & Expendi'!Q33="", "", VALUE(SUBSTITUTE('Jilla Parishad Income & Expendi'!Q33, ",", ""))) -> 5038 | S33: =IF('Jilla Parishad Income & Expendi'!R33="", "", VALUE(SUBSTITUTE('Jilla Parishad Income & Expendi'!R33, ",", ""))) -> 814 | T33: =IF('Jilla Parishad Income & Expendi'!S33="", "", VALUE(SUBSTITUTE('Jilla Parishad Income & Expendi'!S33, ",", ""))) -> 612 | U33: =IF('Jilla Parishad Income & Expendi'!T33="", "", VALUE(SUBSTITUTE('Jilla Parishad Income & Expendi'!T33, ",", ""))) -> 579 | V33: =IF('Jilla Parishad Income & Expendi'!U33="", "", VALUE(SUBSTITUTE('Jilla Parishad Income & Expendi'!U33, ",", ""))) -> 5 | W33: =IF('Jilla Parishad Income & Expendi'!V33="", "", VALUE(SUBSTITUTE('Jilla Parishad Income & Expendi'!V33, ",", ""))) -> 4499 | ... AD33: =IF('Jilla Parishad Income & Expendi'!AC33="", "", VALUE(SUBSTITUTE('Jilla Parishad Income & Expendi'!AC33, ",", "")))
A34: Bhandara | B34: =IF('Jilla Parishad Income & Expendi'!B34="", "", VALUE(SUBSTITUTE('Jilla Parishad Income & Expendi'!B34, ",", ""))) -> 2015 | C34: =IF('Jilla Parishad Income & Expendi'!C34="", "", VALUE(SUBSTITUTE('Jilla Parishad Income & Expendi'!C34, ",", ""))) -> 13177 | D34: =IF('Jilla Parishad Income & Expendi'!D34="", "", VALUE(SUBSTITUTE('Jilla Parishad Income & Expendi'!D34, ",", ""))) -> 599 | E34: =IF('Jilla Parishad Income & Expendi'!E34="", "", VALUE(SUBSTITUTE('Jilla Parishad Income & Expendi'!E34, ",", ""))) | F34: =IF('Jilla Parishad Income & Expendi'!F34="", "", VALUE(SUBSTITUTE('Jilla Parishad Income & Expendi'!F34, ",", ""))) -> 51509 | G34: =IF('Jilla Parishad Income & Expendi'!G34="", "", VALUE(SUBSTITUTE('Jilla Parishad Income & Expendi'!G34, ",", ""))) | H34: =IF('Jilla Parishad Income & Expendi'!H34="", "", VALUE(SUBSTITUTE('Jilla Parishad Income & Expendi'!H34, ",", ""))) | I34: =IF('Jilla Parishad Income & Expendi'!I34="", "", VALUE(SUBSTITUTE('Jilla Parishad Income & Expendi'!I34, ",", ""))) | J34: =IF('Jilla Parishad Income & Expendi'!J34="", "", VALUE(SUBSTITUTE('Jilla Parishad Income & Expendi'!J34, ",", ""))) -> 2326 | K34: =SUM(F34:J34) -> 53835 | L34: =IF('Jilla Parishad Income & Expendi'!K34="", "", VALUE(SUBSTITUTE('Jilla Parishad Income & Expendi'!K34, ",", ""))) -> 374 | M34: =IF('Jilla Parishad Income & Expendi'!L34="", "", VALUE(SUBSTITUTE('Jilla Parishad Income & Expendi'!L34, ",", ""))) -> 3750 | P34: =IF('Jilla Parishad Income & Expendi'!O34="", "", VALUE(SUBSTITUTE('Jilla Parishad Income & Expendi'!O34, ",", ""))) -> 6264 | Q34: =IF('Jilla Parishad Income & Expendi'!P34="", "", VALUE(SUBSTITUTE('Jilla Parishad Income & Expendi'!P34, ",", ""))) -> 24995 | R34: =IF('Jilla Parishad Income & Expendi'!Q34="", "", VALUE(SUBSTITUTE('Jilla Parishad Income & Expendi'!Q34, ",", ""))) -> 3659 | S34: =IF('Jilla Parishad Income & Expendi'!R34="", "", VALUE(SUBSTITUTE('Jilla Parishad Income & Expendi'!R34, ",", ""))) -> 1805 | T34: =IF('Jilla Parishad Income & Expendi'!S34="", "", VALUE(SUBSTITUTE('Jilla Parishad Income & Expendi'!S34, ",", ""))) -> 601 | U34: =IF('Jilla Parishad Income & Expendi'!T34="", "", VALUE(SUBSTITUTE('Jilla Parishad Income & Expendi'!T34, ",", ""))) -> 647 | V34: =IF('Jilla Parishad Income & Expendi'!U34="", "", VALUE(SUBSTITUTE('Jilla Parishad Income & Expendi'!U34, ",", ""))) -> 8 | W34: =IF('Jilla Parishad Income & Expendi'!V34="", "", VALUE(SUBSTITUTE('Jilla Parishad Income & Expendi'!V34, ",", ""))) -> 3339 | ... AD34: =IF('Jilla Parishad Income & Expendi'!AC34="", "", VALUE(SUBSTITUTE('Jilla Parishad Income & Expendi'!AC34, ",", "")))
